Error ID: 52e44931-1ebb-4d0d-ab5b-f801b66cac61
Command: freemoney
User: hickwhither (ID: 403476178549211156)
Guild: üêßüêßüêß (ID: 1275798785318064138)

Traceback:
Traceback (most recent call last):
  File "E:\projects\TogetherCode\.venv\Lib\site-packages\discord\ext\commands\core.py", line 235, in wrapped
    ret = await coro(*args, **kwargs)
          ^^^^^^^^^^^^^^^^^^^^^^^^^^^
  File "E:\projects\TogetherCode\cogs\economy\economy.py", line 30, in freemoney
    self.db.commit()
  File "E:\projects\TogetherCode\.venv\Lib\site-packages\sqlalchemy\orm\session.py", line 2028, in commit
    trans.commit(_to_root=True)
  File "<string>", line 2, in commit
  File "E:\projects\TogetherCode\.venv\Lib\site-packages\sqlalchemy\orm\state_changes.py", line 139, in _go
    ret_value = fn(self, *arg, **kw)
                ^^^^^^^^^^^^^^^^^^^^
  File "E:\projects\TogetherCode\.venv\Lib\site-packages\sqlalchemy\orm\session.py", line 1313, in commit
    self._prepare_impl()
  File "<string>", line 2, in _prepare_impl
  File "E:\projects\TogetherCode\.venv\Lib\site-packages\sqlalchemy\orm\state_changes.py", line 139, in _go
    ret_value = fn(self, *arg, **kw)
                ^^^^^^^^^^^^^^^^^^^^
  File "E:\projects\TogetherCode\.venv\Lib\site-packages\sqlalchemy\orm\session.py", line 1288, in _prepare_impl
    self.session.flush()
  File "E:\projects\TogetherCode\.venv\Lib\site-packages\sqlalchemy\orm\session.py", line 4352, in flush
    self._flush(objects)
  File "E:\projects\TogetherCode\.venv\Lib\site-packages\sqlalchemy\orm\session.py", line 4487, in _flush
    with util.safe_reraise():
  File "E:\projects\TogetherCode\.venv\Lib\site-packages\sqlalchemy\util\langhelpers.py", line 146, in __exit__
    raise exc_value.with_traceback(exc_tb)
  File "E:\projects\TogetherCode\.venv\Lib\site-packages\sqlalchemy\orm\session.py", line 4448, in _flush
    flush_context.execute()
  File "E:\projects\TogetherCode\.venv\Lib\site-packages\sqlalchemy\orm\unitofwork.py", line 466, in execute
    rec.execute(self)
  File "E:\projects\TogetherCode\.venv\Lib\site-packages\sqlalchemy\orm\unitofwork.py", line 642, in execute
    util.preloaded.orm_persistence.save_obj(
  File "E:\projects\TogetherCode\.venv\Lib\site-packages\sqlalchemy\orm\persistence.py", line 85, in save_obj
    _emit_update_statements(
  File "E:\projects\TogetherCode\.venv\Lib\site-packages\sqlalchemy\orm\persistence.py", line 912, in _emit_update_statements
    c = connection.execute(
        ^^^^^^^^^^^^^^^^^^^
  File "E:\projects\TogetherCode\.venv\Lib\site-packages\sqlalchemy\engine\base.py", line 1418, in execute
    return meth(
           ^^^^^
  File "E:\projects\TogetherCode\.venv\Lib\site-packages\sqlalchemy\sql\elements.py", line 515, in _execute_on_connection
    return connection._execute_clauseelement(
           ^^^^^^^^^^^^^^^^^^^^^^^^^^^^^^^^^^
  File "E:\projects\TogetherCode\.venv\Lib\site-packages\sqlalchemy\engine\base.py", line 1640, in _execute_clauseelement
    ret = self._execute_context(
          ^^^^^^^^^^^^^^^^^^^^^^
  File "E:\projects\TogetherCode\.venv\Lib\site-packages\sqlalchemy\engine\base.py", line 1846, in _execute_context
    return self._exec_single_context(
           ^^^^^^^^^^^^^^^^^^^^^^^^^^
  File "E:\projects\TogetherCode\.venv\Lib\site-packages\sqlalchemy\engine\base.py", line 1986, in _exec_single_context
    self._handle_dbapi_exception(
  File "E:\projects\TogetherCode\.venv\Lib\site-packages\sqlalchemy\engine\base.py", line 2358, in _handle_dbapi_exception
    raise exc_info[1].with_traceback(exc_info[2])
  File "E:\projects\TogetherCode\.venv\Lib\site-packages\sqlalchemy\engine\base.py", line 1967, in _exec_single_context
    self.dialect.do_execute(
  File "E:\projects\TogetherCode\.venv\Lib\site-packages\sqlalchemy\engine\default.py", line 941, in do_execute
    cursor.execute(statement, parameters)
OverflowError: Python int too large to convert to SQLite INTEGER

The above exception was the direct cause of the following exception:

Traceback (most recent call last):
  File "E:\projects\TogetherCode\.venv\Lib\site-packages\discord\ext\commands\bot.py", line 1366, in invoke
    await ctx.command.invoke(ctx)
  File "E:\projects\TogetherCode\.venv\Lib\site-packages\discord\ext\commands\core.py", line 1029, in invoke
    await injected(*ctx.args, **ctx.kwargs)  # type: ignore
    ^^^^^^^^^^^^^^^^^^^^^^^^^^^^^^^^^^^^^^^
  File "E:\projects\TogetherCode\.venv\Lib\site-packages\discord\ext\commands\core.py", line 244, in wrapped
    raise CommandInvokeError(exc) from exc
discord.ext.commands.errors.CommandInvokeError: Command raised an exception: OverflowError: Python int too large to convert to SQLite INTEGER
